<?xml version="1.0" encoding="UTF-8"?>
<robot generator="Robot 4.1.3 (Python 3.8.10 on linux)" generated="20220629 16:17:50.772" rpa="false" schemaversion="2">
<suite id="s1" name="Test Connection" source="/home/marcelo/robot_framework/healthcheck/test_connection.robot">
<test id="s1-t1" name="Connect to devices">
<kw name="use genie testbed &quot;${testbed}&quot;">
<msg timestamp="20220629 16:17:50.912" level="FAIL">No keyword with name 'use genie testbed "${testbed}"' found.</msg>
<status status="FAIL" starttime="20220629 16:17:50.912" endtime="20220629 16:17:50.912"/>
</kw>
<kw name="connect to device &quot;DCI-EQX-01&quot;">
<status status="NOT RUN" starttime="20220629 16:17:50.913" endtime="20220629 16:17:50.914"/>
</kw>
<kw name="connect to device &quot;DCI-EQX-02&quot;">
<status status="NOT RUN" starttime="20220629 16:17:50.914" endtime="20220629 16:17:50.915"/>
</kw>
<doc>Define the hosts to connect and test connection</doc>
<tag>equinix</tag>
<status status="FAIL" starttime="20220629 16:17:50.911" endtime="20220629 16:17:50.915">No keyword with name 'use genie testbed "${testbed}"' found.</status>
</test>
<status status="FAIL" starttime="20220629 16:17:50.772" endtime="20220629 16:17:50.916"/>
</suite>
<statistics>
<total>
<stat pass="0" fail="1" skip="0">All Tests</stat>
</total>
<tag>
<stat pass="0" fail="1" skip="0">equinix</stat>
</tag>
<suite>
<stat pass="0" fail="1" skip="0" id="s1" name="Test Connection">Test Connection</stat>
</suite>
</statistics>
<errors>
<msg timestamp="20220629 16:17:50.789" level="ERROR">Error in file '/home/marcelo/robot_framework/healthcheck/test_connection.robot' on line 5: Importing library 'ats.robot.pyATSRobot' failed: ModuleNotFoundError: No module named 'ats'
Traceback (most recent call last):
  None
PYTHONPATH:
  /home/marcelo/robot_framework/env_robot/bin
  /usr/lib/python38.zip
  /usr/lib/python3.8
  /usr/lib/python3.8/lib-dynload
  /home/marcelo/robot_framework/env_robot/lib/python3.8/site-packages</msg>
<msg timestamp="20220629 16:17:50.910" level="ERROR">Error in file '/home/marcelo/robot_framework/healthcheck/test_connection.robot' on line 6: Importing library 'genie.libs.robot.GenieRobot' failed: ImportError: cannot import name configuration
Traceback (most recent call last):
  File "/home/marcelo/robot_framework/env_robot/lib/python3.8/site-packages/genie/libs/robot/GenieRobot.py", line 11, in &lt;module&gt;
    from pyats.utils.objects import find, R
  File "src/pyats/utils/objects.py", line 4, in init pyats.utils.objects
  File "/home/marcelo/robot_framework/env_robot/lib/python3.8/site-packages/pyats/topology/__init__.py", line 52, in &lt;module&gt;
    from .link import Link, LinkBase
  File "src/pyats/topology/link.py", line 5, in init pyats.topology.link
  File "src/pyats/topology/factory.py", line 5, in init pyats.topology.factory
PYTHONPATH:
  /home/marcelo/robot_framework/env_robot/bin
  /usr/lib/python38.zip
  /usr/lib/python3.8
  /usr/lib/python3.8/lib-dynload
  /home/marcelo/robot_framework/env_robot/lib/python3.8/site-packages</msg>
</errors>
</robot>
